Workbook
Name hola: #REF!

Sheet Constants
A2: Sampling data | B2: 44413
A3: Sampling mission | B3: Gales Creek 03 (GC-21-03 or GC-03)
A4: Sampling instrument
A5: Core code
A6: Ocean/Sea
A7: Sampling area | W7: Grain Size Data Available
A8: Sampling depth (m)
C9: '
A10: Latitude (°N)
A11: Longitude (°W)
A12: Latitude (decimal degrees)
A13: Longitude (decimal degrees)
A14: Sampling date | B14: 44413
A15: Sampling date (yr) | B15: =2021+(8-1)/12+(5-1)/365.24 -> 2021.5943 | D15: 2021+(month-1)/12+(day-1)/365.24
A16: Internal diameter ( f, cm) | B16: 10 | C16: * 4in=10.2cm, 3in=7.52cm
A17: Uncertainty u(f) | B17: 0.1
A18: Surface (cm2) | B18: =PI()*(B16/2)^2 -> 78.539816
A19: Uncertainty u(S) | B19: =PI()*B16*B17/2 -> 1.5707963
A20: Core length (cm)
A22: Pb-210
A23: Half-life (t½, yr) | B23: 22.23 | C23: Source DDEP, 2010
A24: Uncertainty u(t½) | B24: 0.12 | C24: =B24/B23*100 -> 0.53981107 | D24: (u, %)
A25: Disintegration constant (l, yr-1) | B25: =LN(2)/B23 -> 0.03118071
A26: Uncertainty u(l) | B26: =B25*C24/100 -> 0.00016831692 | C26: =B26/B25*100 -> 0.53981107 | D26: (u,%)

Sheet Masses
E1: from DBD tab | F1: ~2%
E2: section | G2: Aerial | I2: Cumulative
B3: top of | D3: thickness | E3: Dry Bulk | G3: Dry Mass | I3: mass depth | K3: Mass Depth
B4: interval | C4: md-depth | D4: section | E4: Density | G4: (by area) | I4: layer | K4: Section
A5: Code | B5: z(i) | C5: zi | D5: Δzi | E5: DBD | F5: u(DBD) | G5: Δmi/S | H5: u(Δmi/S) | I5: m(i) | J5: u(m(i)) | K5: mi | L5: u(mi)
B6: (cm) | C6: (cm) | D6: (cm) | E6: (g cm-3) | G6: (g cm-2) | I6: (g cm-2) | K6: (g cm-2)
B7: 0 | I7: 0 | J7: =0 -> 0
A8: 0-1 | C8: =(B7+B9)/2 -> 0.5 | D8: =B9-B7 -> 1 | E8: 0.22610392 | F8: 0.0048459592 | G8: =D8*E8 -> 0.22610392 | H8: =F8*D8 -> 0.0048459592 | K8: =AVERAGE(I7:I9) -> 0.11305196 | L8: =SQRT(SUMSQ(J9,J7))/2 -> 0.0024229796
B9: =B7+1 -> 1 | I9: =I7+(G8) -> 0.22610392 | J9: =SQRT(H8^2+J7^2) -> 0.0048459592
A10: 1-2 | C10: =(B9+B11)/2 -> 1.5 | D10: =B11-B9 -> 1 | E10: 0.27468829 | F10: 0.004320619 | G10: =D10*E10 -> 0.27468829 | H10: =F10*D10 -> 0.004320619 | K10: =AVERAGE(I9:I11) -> 0.36344807 | L10: =SQRT(SUMSQ(J11,J9))/2 -> 0.0040507527
B11: =B9+1 -> 2 | I11: =I9+(G10) -> 0.50079222 | J11: =SQRT(H10^2+J9^2) -> 0.0064923855
A12: 2-3 | C12: =(B11+B13)/2 -> 2.5 | D12: =B13-B11 -> 1 | E12: 0.28437784 | F12: 0.0046343253 | G12: =D12*E12 -> 0.28437784 | H12: =F12*D12 -> 0.0046343253 | K12: =AVERAGE(I11:I13) -> 0.64298113 | L12: =SQRT(SUMSQ(J13,J11))/2 -> 0.0051424486
B13: =B11+1 -> 3 | I13: =I11+(G12) -> 0.78517005 | J13: =SQRT(H12^2+J11^2) -> 0.0079767186
A14: 3-4 | C14: =(B13+B15)/2 -> 3.5 | D14: =B15-B13 -> 1 | E14: 0.29235443 | F14: 0.0046709014 | G14: =D14*E14 -> 0.29235443 | H14: =F14*D14 -> 0.0046709014 | K14: =AVERAGE(I13:I15) -> 0.93134727 | L14: =SQRT(SUMSQ(J15,J13))/2 -> 0.0061047809
B15: =B13+1 -> 4 | I15: =I13+(G14) -> 1.0775245 | J15: =SQRT(H14^2+J13^2) -> 0.009243666
A16: 4-5 | C16: =(B15+B17)/2 -> 4.5 | D16: =B17-B15 -> 1 | E16: 0.29561971 | F16: 0.0046395966 | G16: =D16*E16 -> 0.29561971 | H16: =F16*D16 -> 0.0046395966 | K16: =AVERAGE(I15:I17) -> 1.2253343 | L16: =SQRT(SUMSQ(J17,J15))/2 -> 0.0069357151
B17: =B15+1 -> 5 | I17: =I15+(G16) -> 1.3731442 | J17: =SQRT(H16^2+J15^2) -> 0.010342689
A18: 5-6 | C18: =(B17+B19)/2 -> 5.5 | D18: =B19-B17 -> 1 | E18: 0.29474803 | F18: 0.0047632445 | G18: =D18*E18 -> 0.29474803 | H18: =F18*D18 -> 0.0047632445 | K18: =AVERAGE(I17:I19) -> 1.5205182 | L18: =SQRT(SUMSQ(J19,J17))/2 -> 0.0076914064
B19: =B17+1 -> 6 | I19: =I17+(G18) -> 1.6678922 | J19: =SQRT(H18^2+J17^2) -> 0.011386822
A20: 6-7 | C20: =(B19+B21)/2 -> 6.5 | D20: =B21-B19 -> 1 | E20: 0.28910411 | F20: 0.0048555386 | G20: =D20*E20 -> 0.28910411 | H20: =F20*D20 -> 0.0048555386 | K20: =AVERAGE(I19:I21) -> 1.8124443 | L20: =SQRT(SUMSQ(J21,J19))/2 -> 0.0084097516
B21: =B19+1 -> 7 | I21: =I19+(G20) -> 1.9569963 | J21: =SQRT(H20^2+J19^2) -> 0.012378852
A22: 7-8 | C22: =(B21+B23)/2 -> 7.5 | D22: =B23-B21 -> 1 | E22: 0.28271773 | F22: 0.0048802341 | G22: =D22*E22 -> 0.28271773 | H22: =F22*D22 -> 0.0048802341 | K22: =AVERAGE(I21:I23) -> 2.0983552 | L22: =SQRT(SUMSQ(J23,J21))/2 -> 0.0090869223
B23: =B21+1 -> 8 | I23: =I21+(G22) -> 2.2397141 | J23: =SQRT(H22^2+J21^2) -> 0.013306113
A24: 8-9 | C24: =(B23+B25)/2 -> 8.5 | D24: =B25-B23 -> 1 | E24: 0.28351579 | F24: 0.0048909502 | G24: =D24*E24 -> 0.28351579 | H24: =F24*D24 -> 0.0048909502 | K24: =AVERAGE(I23:I25) -> 2.381472 | L24: =SQRT(SUMSQ(J25,J23))/2 -> 0.0097214544
B25: =B23+1 -> 9 | I25: =I23+(G24) -> 2.5232299 | J25: =SQRT(H24^2+J23^2) -> 0.014176532
A26: 9-10 | C26: =(B25+B27)/2 -> 9.5 | D26: =B27-B25 -> 1 | E26: 0.264014 | F26: 0.004869226 | G26: =D26*E26 -> 0.264014 | H26: =F26*D26 -> 0.004869226 | K26: =AVERAGE(I25:I27) -> 2.6552369 | L26: =SQRT(SUMSQ(J27,J25))/2 -> 0.010315734
B27: =B25+1 -> 10 | I27: =I25+(G26) -> 2.7872439 | J27: =SQRT(H26^2+J25^2) -> 0.014989443
A28: 10-11 | C28: =(B27+B29)/2 -> 10.5 | D28: =B29-B27 -> 1 | E28: 0.26920853 | F28: 0.0048821689 | G28: =D28*E28 -> 0.26920853 | H28: =F28*D28 -> 0.0048821689 | K28: =AVERAGE(I27:I29) -> 2.9218481 | L28: =SQRT(SUMSQ(J29,J27))/2 -> 0.010876608
B29: =B27+1 -> 11 | I29: =I27+(G28) -> 3.0564524 | J29: =SQRT(H28^2+J27^2) -> 0.015764485
A30: 11-12 | C30: =(B29+B31)/2 -> 11.5 | D30: =B31-B29 -> 1 | E30: 0.25316299 | F30: 0.0049572736 | G30: =D30*E30 -> 0.25316299 | H30: =F30*D30 -> 0.0049572736 | K30: =AVERAGE(I29:I31) -> 3.1830339 | L30: =SQRT(SUMSQ(J31,J29))/2 -> 0.011419419
B31: =B29+1 -> 12 | I31: =I29+(G30) -> 3.3096154 | J31: =SQRT(H30^2+J29^2) -> 0.016525542
A32: 12-13 | C32: =(B31+B33)/2 -> 12.5 | D32: =B33-B31 -> 1 | E32: 0.26930936 | F32: 0.0050148835 | G32: =D32*E32 -> 0.26930936 | H32: =F32*D32 -> 0.0050148835 | K32: =AVERAGE(I31:I33) -> 3.4442701 | L32: =SQRT(SUMSQ(J33,J31))/2 -> 0.011951319
B33: =B31+1 -> 13 | I33: =I31+(G32) -> 3.5789247 | J33: =SQRT(H32^2+J31^2) -> 0.017269702
A34: 13-14 | C34: =(B33+B35)/2 -> 13.5 | D34: =B35-B33 -> 1 | E34: 0.26964695 | F34: 0.004594512 | G34: =D34*E34 -> 0.26964695 | H34: =F34*D34 -> 0.004594512 | K34: =AVERAGE(I33:I35) -> 3.7137482 | L34: =SQRT(SUMSQ(J35,J33))/2 -> 0.012425727
B35: =B33+1 -> 14 | I35: =I33+(G34) -> 3.8485717 | J35: =SQRT(H34^2+J33^2) -> 0.017870426
A36: 14-15 | C36: =(B35+B37)/2 -> 14.5 | D36: =B37-B35 -> 1 | E36: 0.27456196 | F36: 0.0042514282 | G36: =D36*E36 -> 0.27456196 | H36: =F36*D36 -> 0.0042514282 | K36: =AVERAGE(I35:I37) -> 3.9858527 | L36: =SQRT(SUMSQ(J37,J35))/2 -> 0.012813849
B37: =B35+1 -> 15 | I37: =I35+(G36) -> 4.1231336 | J37: =SQRT(H36^2+J35^2) -> 0.01836918
A38: 15-16 | C38: =(B37+B39)/2 -> 15.5 | D38: =B39-B37 -> 1 | E38: 0.26741339 | F38: 0.0047609662 | G38: =D38*E38 -> 0.26741339 | H38: =F38*D38 -> 0.0047609662 | K38: =AVERAGE(I37:I39) -> 4.2568403 | L38: =SQRT(SUMSQ(J39,J37))/2 -> 0.013205305
B39: =B37+1 -> 16 | I39: =I37+(G38) -> 4.390547 | J39: =SQRT(H38^2+J37^2) -> 0.018976132
A40: 16-17 | C40: =(B39+B41)/2 -> 16.5 | D40: =B41-B39 -> 1 | E40: 0.27017935 | F40: 0.0050658432 | G40: =D40*E40 -> 0.27017935 | H40: =F40*D40 -> 0.0050658432 | K40: =AVERAGE(I39:I41) -> 4.5256367 | L40: =SQRT(SUMSQ(J41,J39))/2 -> 0.013655127
...

Sheet Concentrations
G1: Excess | K1: Inventory
A2: middle of | B2: Code | C2: Pb-210 | D2: u(210Pb) | E2: Ra-226 | F2: u(226Ra) | G2: Ci | H2: u(Ci) | I2: C(i) | J2: u(C(i)) | K2: ΔAi | L2: u(ΔAi) | M2: middle of | N2: Mass Depth | O2: ln(Ci) | P2: uln(Ci)
A3: Inverval | C3: (dpm g-1) | E3: (dpm g-1) | G3: (dpm g-1) | I3: (dpm g-1) | K3: (dpm cm-2) | M3: Inverval (cm) | N3: mi (g cm-2)
I4: ='C0 CA'!B13 -> 12.840732 | J4: ='C0 CA'!C13 -> 0.99407026
A5: =Masses!C8 -> 0.5 | B5: =Masses!A8 -> 0-1 | C5: 11.890992 | D5: 0.07218209 | E5: 0.7 | F5: 0.072470619 | G5: =C5-E5 -> 11.190992 | H5: =SQRT(SUMSQ(D5,F5)) -> 0.10228512 | K5: =(G5*Masses!G8) -> 2.5303272 | L5: =K5*SQRT(SUMSQ(H5/G5,Masses!H8/Masses!G8)) -> 0.058956529 | M5: =A5 -> 0.5 | N5: =Masses!K8 -> 0.11305196 | O5: =LN(G5) -> 2.4151092 | P5: =(H5/G5) -> 0.0091399508
I6: =(G5+G7)/2 -> 10.796377 | J6: =SQRT(SUMSQ(H5,H7))/2 -> 0.072326499
A7: =Masses!C10 -> 1.5 | B7: =Masses!A10 -> 1-2 | C7: 11.101763 | D7: 0.072182091 | E7: 0.7 | F7: 0.072470619 | G7: =C7-E7 -> 10.401763 | H7: =SQRT(SUMSQ(D7,F7)) -> 0.10228512 | K7: =(G7*Masses!G10) -> 2.8572425 | L7: =K7*SQRT(SUMSQ(H7/G7,Masses!H10/Masses!G10)) -> 0.053001915 | M7: =A7 -> 1.5 | N7: =Masses!K10 -> 0.36344807 | O7: =LN(G7) -> 2.3419753 | P7: =(H7/G7) -> 0.0098334404
I8: =(G7+G9)/2 -> 10.983338 | J8: =SQRT(SUMSQ(H7,H9))/2 -> 0.072326498
A9: =Masses!C12 -> 2.5 | B9: =Masses!A12 -> 2-3 | C9: 12.264914 | D9: 0.072182089 | E9: 0.7 | F9: 0.072470619 | G9: =C9-E9 -> 11.564914 | H9: =SQRT(SUMSQ(D9,F9)) -> 0.10228511 | K9: =(G9*Masses!G12) -> 3.2888051 | L9: =K9*SQRT(SUMSQ(H9/G9,Masses!H12/Masses!G12)) -> 0.060980118 | M9: =A9 -> 2.5 | N9: =Masses!K12 -> 0.64298113 | O9: =LN(G9) -> 2.4479758 | P9: =(H9/G9) -> 0.008844434
I10: =(G9+G11)/2 -> 11.249076 | J10: =SQRT(SUMSQ(H9,H11))/2 -> 0.072326498
A11: =Masses!C14 -> 3.5 | B11: =Masses!A14 -> 3-4 | C11: 11.633238 | D11: 0.07218209 | E11: 0.7 | F11: 0.072470619 | G11: =C11-E11 -> 10.933238 | H11: =SQRT(SUMSQ(D11,F11)) -> 0.10228511 | K11: =(G11*Masses!G14) -> 3.1963807 | L11: =K11*SQRT(SUMSQ(H11/G11,Masses!H14/Masses!G14)) -> 0.059179121 | M11: =A11 -> 3.5 | N11: =Masses!K14 -> 0.93134727 | O11: =LN(G11) -> 2.3918075 | P11: =(H11/G11) -> 0.0093554271
I12: =(G11+G13)/2 -> 10.822892 | J12: =SQRT(SUMSQ(H11,H13))/2 -> 0.072326499
A13: =Masses!C16 -> 4.5 | B13: =Masses!A16 -> 4-5 | C13: 11.412545 | D13: 0.072182091 | E13: 0.7 | F13: 0.072470619 | G13: =C13-E13 -> 10.712545 | H13: =SQRT(SUMSQ(D13,F13)) -> 0.10228512 | K13: =(G13*Masses!G16) -> 3.1668394 | L13: =K13*SQRT(SUMSQ(H13/G13,Masses!H16/Masses!G16)) -> 0.058177175 | M13: =A13 -> 4.5 | N13: =Masses!K16 -> 1.2253343 | O13: =LN(G13) -> 2.3714155 | P13: =(H13/G13) -> 0.0095481623
I14: =(G13+G15)/2 -> 10.266014 | J14: =SQRT(SUMSQ(H13,H15))/2 -> 0.0723265
A15: =Masses!C18 -> 5.5 | B15: =Masses!A18 -> 5-6 | C15: 10.519484 | D15: 0.072182095 | E15: 0.7 | F15: 0.072470619 | G15: =C15-E15 -> 9.8194838 | H15: =SQRT(SUMSQ(D15,F15)) -> 0.10228512 | K15: =(G15*Masses!G18) -> 2.8942735 | L15: =K15*SQRT(SUMSQ(H15/G15,Masses!H18/Masses!G18)) -> 0.05564709 | M15: =A15 -> 5.5 | N15: =Masses!K18 -> 1.5205182 | O15: =LN(G15) -> 2.2843686 | P15: =(H15/G15) -> 0.010416547
I16: =(G15+G17)/2 -> 9.7546532 | J16: =SQRT(SUMSQ(H15,H17))/2 -> 0.072326502
A17: =Masses!C20 -> 6.5 | B17: =Masses!A20 -> 6-7 | C17: 10.389823 | D17: 0.072182097 | E17: 0.7 | F17: 0.072470619 | G17: =C17-E17 -> 9.6898226 | H17: =SQRT(SUMSQ(D17,F17)) -> 0.10228512 | K17: =(G17*Masses!G20) -> 2.8013675 | L17: =K17*SQRT(SUMSQ(H17/G17,Masses!H20/Masses!G20)) -> 0.055570534 | M17: =A17 -> 6.5 | N17: =Masses!K20 -> 1.8124443 | O17: =LN(G17) -> 2.2710761 | P17: =(H17/G17) -> 0.010555933
I18: =(G17+G19)/2 -> 9.0905778 | J18: =SQRT(SUMSQ(H17,H19))/2 -> 0.072326504
A19: =Masses!C22 -> 7.5 | B19: =Masses!A22 -> 7-8 | C19: 9.1913329 | D19: 0.072182106 | E19: 0.7 | F19: 0.072470619 | G19: =C19-E19 -> 8.4913329 | H19: =SQRT(SUMSQ(D19,F19)) -> 0.10228513 | K19: =(G19*Masses!G22) -> 2.4006503 | L19: =K19*SQRT(SUMSQ(H19/G19,Masses!H22/Masses!G22)) -> 0.050532052 | M19: 7.5 | N19: =Masses!K22 -> 2.0983552 | O19: =LN(G19) -> 2.139046 | P19: =(H19/G19) -> 0.012045827
I20: =(G19+G21)/2 -> 7.2985302 | J20: =SQRT(SUMSQ(H19,H21))/2 -> 0.07232651
A21: =Masses!C24 -> 8.5 | B21: =Masses!A24 -> 8-9 | C21: 6.8057275 | D21: 0.07218212 | E21: 0.7 | F21: 0.072470619 | G21: =C21-E21 -> 6.1057275 | H21: =SQRT(SUMSQ(D21,F21)) -> 0.10228514 | K21: =(G21*Masses!G24) -> 1.7310702 | L21: =K21*SQRT(SUMSQ(H21/G21,Masses!H24/Masses!G24)) -> 0.04162638 | M21: 8.5 | N21: =Masses!K24 -> 2.381472 | O21: =LN(G21) -> 1.8092273 | P21: =(H21/G21) -> 0.016752326
I22: =(G21+G23)/2 -> 6.1282044 | J22: =SQRT(SUMSQ(H21,H23))/2 -> 0.072326514
A23: =Masses!C26 -> 9.5 | B23: =Masses!A26 -> 9-10 | C23: 6.8506814 | D23: 0.072182122 | E23: 0.7 | F23: 0.072470619 | G23: =C23-E23 -> 6.1506814 | H23: =SQRT(SUMSQ(D23,F23)) -> 0.10228514 | K23: =(G23*Masses!G26) -> 1.623866 | L23: =K23*SQRT(SUMSQ(H23/G23,Masses!H26/Masses!G26)) -> 0.040326174 | M23: 9.5 | N23: =Masses!K26 -> 2.6552369 | O23: =LN(G23) -> 1.8165629 | P23: =(H23/G23) -> 0.016629887
I24: =(G23+G25)/2 -> 5.9539269 | J24: =SQRT(SUMSQ(H23,H25))/2 -> 0.072326517
A25: =Masses!C28 -> 10.5 | B25: =Masses!A28 -> 10-11 | C25: 6.4571724 | D25: 0.072182133 | E25: 0.7 | F25: 0.072470619 | G25: =C25-E25 -> 5.7571724 | H25: =SQRT(SUMSQ(D25,F25)) -> 0.10228515 | K25: =(G25*Masses!G28) -> 1.5498799 | L25: =K25*SQRT(SUMSQ(H25/G25,Masses!H28/Masses!G28)) -> 0.039347987 | M25: 10.5 | N25: =Masses!K28 -> 2.9218481 | O25: =LN(G25) -> 1.7504465 | P25: =(H25/G25) -> 0.017766559
I26: =(G25+G27)/2 -> 5.1336713 | J26: =SQRT(SUMSQ(H25,H27))/2 -> 0.072326533
A27: =Masses!C30 -> 11.5 | B27: =Masses!A30 -> 11-12 | C27: 5.2101702 | D27: 0.072182184 | E27: 0.7 | F27: 0.072470619 | G27: =C27-E27 -> 4.5101702 | H27: =SQRT(SUMSQ(D27,F27)) -> 0.10228518 | K27: =(G27*Masses!G30) -> 1.1418082 | L27: =K27*SQRT(SUMSQ(H27/G27,Masses!H30/Masses!G30)) -> 0.034211527 | M27: 11.5 | N27: =Masses!K30 -> 3.1830339 | O27: =LN(G27) -> 1.5063349 | P27: =(H27/G27) -> 0.022678785
I28: =(G27+G29)/2 -> 4.4866318 | J28: =SQRT(SUMSQ(H27,H29))/2 -> 0.072326553
A29: =Masses!C32 -> 12.5 | B29: =Masses!A32 -> 12-13 | C29: 5.1630933 | D29: 0.072182217 | E29: 0.7 | F29: 0.072470619 | G29: =C29-E29 -> 4.4630933 | H29: =SQRT(SUMSQ(D29,F29)) -> 0.1022852 | K29: =(G29*Masses!G32) -> 1.2019528 | L29: =K29*SQRT(SUMSQ(H29/G29,Masses!H32/Masses!G32)) -> 0.035492974 | M29: 12.5 | N29: =Masses!K32 -> 3.4442701 | O29: =LN(G29) -> 1.4958421 | P29: =(H29/G29) -> 0.022918007
I30: =(G29+G31)/2 -> 4.8135706 | J30: =SQRT(SUMSQ(H29,H31))/2 -> 0.072326554
A31: =Masses!C34 -> 13.5 | B31: =Masses!A34 -> 13-14 | C31: 5.8640479 | D31: 0.072182187 | E31: 0.7 | F31: 0.072470619 | G31: =C31-E31 -> 5.1640479 | H31: =SQRT(SUMSQ(D31,F31)) -> 0.10228518 | K31: =(G31*Masses!G34) -> 1.3924698 | L31: =K31*SQRT(SUMSQ(H31/G31,Masses!H34/Masses!G34)) -> 0.036381888 | M31: 13.5 | N31: =Masses!K34 -> 3.7137482 | O31: =LN(G31) -> 1.6417207 | P31: =(H31/G31) -> 0.019807172
I32: =(G31+G33)/2 -> 5.2754335 | J32: =SQRT(SUMSQ(H31,H33))/2 -> 0.072326551
A33: =Masses!C36 -> 14.5 | B33: =Masses!A36 -> 14-15 | C33: 6.0868192 | D33: 0.072182203 | E33: 0.7 | F33: 0.072470619 | G33: =C33-E33 -> 5.3868192 | H33: =SQRT(SUMSQ(D33,F33)) -> 0.10228519 | K33: =(G33*Masses!G36) -> 1.4790156 | L33: =K33*SQRT(SUMSQ(H33/G33,Masses!H36/Masses!G36)) -> 0.036237779 | M33: 14.5 | N33: =Masses!K36 -> 3.9858527 | O33: =LN(G33) -> 1.6839551 | P33: =(H33/G33) -> 0.018988051
I34: =(G33+G35)/2 -> 5.1968817 | J34: =SQRT(SUMSQ(H33,H35))/2 -> 0.072326557
A35: =Masses!C38 -> 15.5 | B35: =Masses!A38 -> 15-16 | C35: 5.7069443 | D35: 0.072182213 | E35: 0.7 | F35: 0.072470619 | G35: =C35-E35 -> 5.0069443 | H35: =SQRT(SUMSQ(D35,F35)) -> 0.1022852 | K35: =(G35*Masses!G38) -> 1.3389239 | L35: =K35*SQRT(SUMSQ(H35/G35,Masses!H38/Masses!G38)) -> 0.036282236 | M35: 15.5 | N35: =Masses!K38 -> 4.2568403 | O35: =LN(G35) -> 1.6108258 | P35: =(H35/G35) -> 0.020428668
I36: =(G35+G37)/2 -> 4.6544229 | J36: =SQRT(SUMSQ(H35,H37))/2 -> 0.07232656
A37: =Masses!C40 -> 16.5 | B37: =Masses!A40 -> 16-17 | C37: 5.0019015 | D37: 0.072182212 | E37: 0.7 | F37: 0.072470619 | G37: =C37-E37 -> 4.3019015 | H37: =SQRT(SUMSQ(D37,F37)) -> 0.1022852 | K37: =(G37*Masses!G40) -> 1.162285 | L37: =K37*SQRT(SUMSQ(H37/G37,Masses!H40/Masses!G40)) -> 0.035194273 | M37: 16.5 | N37: =Masses!K40 -> 4.5256367 | O37: =LN(G37) -> 1.4590571 | P37: =(H37/G37) -> 0.023776742
I38: =(G37+G39)/2 -> 3.8710459 | J38: =SQRT(SUMSQ(H37,H39))/2 -> 0.072326586
A39: =Masses!C42 -> 17.5 | B39: =Masses!A42 -> 17-18 | C39: 4.1401902 | D39: 0.072182318 | E39: 0.7 | F39: 0.072470619 | G39: =C39-E39 -> 3.4401902 | H39: =SQRT(SUMSQ(D39,F39)) -> 0.10228528 | K39: =(G39*Masses!G42) -> 0.93382549 | L39: =K39*SQRT(SUMSQ(H39/G39,Masses!H42/Masses!G42)) -> 0.032795482 | M39: 17.5 | N39: =Masses!K42 -> 4.7964493 | O39: =LN(G39) -> 1.2355268 | P39: =(H39/G39) -> 0.029732448
I40: =(G39+G41)/2 -> 3.3769452 | J40: =SQRT(SUMSQ(H39,H41))/2 -> 0.07232662
...

Sheet C0 CA
G2: LINEST
F3: slope | G3: {=LINEST(C18:C27,B18:B27,TRUE,TRUE)} -> -0.23556568 | H3: 2.5526223 | I3: intercept
F4: Std. err slope | G4: 0.048338502 | H4: 0.077415386 | I4: Std. err. Intercept
F5: r2 | G5: 0.74802023 | H5: 0.12566703 | I5: s(y)
F6: F | G6: 23.748581 | H6: 8 | I6: degrees of freedom
F7: regression ss | G7: 0.37504242 | H7: 0.12633763 | I7: residual ss
B9: Coefficients | C9: Std Error
A10: Intercept | B10: =INTERCEPT(C18:C27,B18:B27) -> 2.5526223 | C10: =H4 -> 0.077415386
A11: X Variable 1 | B11: =SLOPE(C18:C27,B18:B27) -> -0.23556568 | C11: =G4 -> 0.048338502
A13: C0 | B13: =EXP(B10) -> 12.840732 | C13: =B13*C10 -> 0.99407026
A16: zi | B16: mi | C16: ln Ci
A17: (cm) | B17: (g cm-2)
A18: {=_xlfn._xlws.FILTER(Concentrations!A5:'Concentrations'!A24,(Concentrations!A5:'Concentrations'!A24<>""))} -> 0.5 | B18: {=_xlfn._xlws.FILTER(Concentrations!N5:'Concentrations'!N24,(Concentrations!N5:'Concentrations'!N24<>""))} -> 0.11305196 | C18: {=_xlfn._xlws.FILTER(Concentrations!O5:'Concentrations'!O24,(Concentrations!O5:'Concentrations'!O24<>""))} -> 2.4151092
A19: 1.5 | B19: 0.36344807 | C19: 2.3419753
A20: 2.5 | B20: 0.64298113 | C20: 2.4479758
A21: 3.5 | B21: 0.93134727 | C21: 2.3918075
A22: 4.5 | B22: 1.2253343 | C22: 2.3714155
A23: 5.5 | B23: 1.5205182 | C23: 2.2843686
A24: 6.5 | B24: 1.8124443 | C24: 2.2710761
A25: 7.5 | B25: 2.0983552 | C25: 2.139046
A26: 8.5 | B26: 2.381472 | C26: 1.8092273
A27: 9.5 | B27: 2.6552369 | C27: 1.8165629
M31: =100*0.03 -> 3

Sheet CA
A2: zi | B2: ln(Ci) | C2: ti | D2: u(ti) | E2: CIC age | F2: ur(l) | G2: ur(C0) | H2: ur(Ci) | I2: t(i) | J2: u(t(i)) | K2: Δt | L2: u(Δt) | M2: s | N2: u(s) | O2: r | P2: u(r ) | Q2: Mass Depth | AI2: CIC Model
A3: (cm) | C3: (yr) | E3: (A.D.) | I3: (yr) | K3: (yr) | M3: (cm yr-1) | O3: (g cm-2 yr-1) | Q3: m | AI3: Excess Pb-210 = Total - supported (226Ra)
I4: 0 | J4: 0
A5: =Masses!C8 -> 0.5 | B5: =Concentrations!O5 -> 2.4151092 | C5: =LN('C0 CA'!$B$13/Concentrations!G5)/Constants!$B$25 -> 4.4102004 | D5: =SQRT(F5^2+G5^2+H5^2)/Constants!$B$25 -> 2.5001548 | E5: =Constants!$B$15-CA!C5 -> 2017.1841 | F5: =Constants!$B$26*C5 -> 0.00074231135 | G5: ='C0 CA'!$C$13/'C0 CA'!$B$13 -> 0.077415386 | H5: =Concentrations!H5/Concentrations!G5 -> 0.0091399508 | K5: =I6-I4 -> 5.5829422 | L5: =SQRT(SUMSQ(J4,J6)) -> 1.768887 | M5: =(Masses!B9-Masses!B7)/K5 -> 0.17911702 | N5: =M5*L5/K5 -> 0.056751039 | O5: =(Masses!I9-Masses!I7)/K5 -> 0.040499062 | P5: =O5*L5/K5 -> 0.012831633 | Q5: =Masses!K8 -> 0.11305196 | AH5: λ= | AI5: 0.03118 | AL5: t = x/So
I6: =AVERAGE(C5,C7) -> 5.5829422 | J6: =SQRT(SUMSQ(D5,D7))/2 -> 1.768887 | AM6: Half Life: t1/2 = 22.23 ± 0.12 yr
A7: =Masses!C10 -> 1.5 | B7: =Concentrations!O7 -> 2.3419753 | C7: =LN('C0 CA'!$B$13/Concentrations!G7)/Constants!$B$25 -> 6.7556841 | D7: =SQRT(F7^2+G7^2+H7^2)/Constants!$B$25 -> 2.5030123 | E7: =Constants!$B$15-CA!C7 -> 2014.8386 | F7: =Constants!$B$26*C7 -> 0.001137096 | G7: ='C0 CA'!$C$13/'C0 CA'!$B$13 -> 0.077415386 | H7: =Concentrations!H7/Concentrations!G7 -> 0.0098334404 | K7: =I8-I6 -> -0.52703512 | L7: =SQRT(SUMSQ(J6,J8)) -> 2.5012989 | M7: =(Masses!B11-Masses!B9)/K7 -> -1.8974068 | N7: =M7*L7/K7 -> 9.0050574 | O7: =(Masses!I11-Masses!I9)/K7 -> -0.52119543 | P7: =O7*L7/K7 -> 2.4735838 | Q7: =Masses!K10 -> 0.36344807 | AM7: Decay Constant: (ln2/t1/2 ) = 0.03118 ± 0.00017 yr-1
I8: =AVERAGE(C7,C9) -> 5.0559071 | J8: =SQRT(SUMSQ(D7,D9))/2 -> 1.7684838
A9: =Masses!C12 -> 2.5 | B9: =Concentrations!O9 -> 2.4479758 | C9: =LN('C0 CA'!$B$13/Concentrations!G9)/Constants!$B$25 -> 3.3561301 | D9: =SQRT(F9^2+G9^2+H9^2)/Constants!$B$25 -> 2.4990136 | E9: =Constants!$B$15-CA!C9 -> 2018.2382 | F9: =Constants!$B$26*C9 -> 0.0005648935 | G9: ='C0 CA'!$C$13/'C0 CA'!$B$13 -> 0.077415386 | H9: =Concentrations!H9/Concentrations!G9 -> 0.008844434 | K9: =I10-I8 -> -0.79908757 | L9: =SQRT(SUMSQ(J8,J10)) -> 2.5005145 | M9: =(Masses!B13-Masses!B11)/K9 -> -1.2514273 | N9: =M9*L9/K9 -> 3.9159814 | O9: =(Masses!I13-Masses!I11)/K9 -> -0.35587818 | P9: =O9*L9/K9 -> 1.1136183 | Q9: =Masses!K12 -> 0.64298113
I10: =AVERAGE(C9,C11) -> 4.2568195 | J10: =SQRT(SUMSQ(D9,D11))/2 -> 1.7677776
A11: =Masses!C14 -> 3.5 | B11: =Concentrations!O11 -> 2.3918075 | C11: =LN('C0 CA'!$B$13/Concentrations!G11)/Constants!$B$25 -> 5.157509 | D11: =SQRT(F11^2+G11^2+H11^2)/Constants!$B$25 -> 2.5010161 | E11: =Constants!$B$15-CA!C11 -> 2016.4368 | F11: =Constants!$B$26*C11 -> 0.00086809603 | G11: ='C0 CA'!$C$13/'C0 CA'!$B$13 -> 0.077415386 | H11: =Concentrations!H11/Concentrations!G11 -> 0.0093554271 | K11: =I12-I10 -> 1.2276879 | L11: =SQRT(SUMSQ(J10,J12)) -> 2.5007134 | M11: =(Masses!B15-Masses!B13)/K11 -> 0.81453927 | N11: =M11*L11/K11 -> 1.6591589 | O11: =(Masses!I15-Masses!I13)/K11 -> 0.23813417 | P11: =O11*L11/K11 -> 0.48506245 | Q11: =Masses!K14 -> 0.93134727
I12: =AVERAGE(C11,C13) -> 5.4845074 | J12: =SQRT(SUMSQ(D11,D13))/2 -> 1.7687651 | AG12: MAR
A13: =Masses!C16 -> 4.5 | B13: =Concentrations!O13 -> 2.3714155 | C13: =LN('C0 CA'!$B$13/Concentrations!G13)/Constants!$B$25 -> 5.8115059 | D13: =SQRT(F13^2+G13^2+H13^2)/Constants!$B$25 -> 2.5018069 | E13: =Constants!$B$15-CA!C13 -> 2015.7828 | F13: =Constants!$B$26*C13 -> 0.00097817479 | G13: ='C0 CA'!$C$13/'C0 CA'!$B$13 -> 0.077415386 | H13: =Concentrations!H13/Concentrations!G13 -> 0.0095481623 | K13: =I14-I12 -> 1.7228438 | L13: =SQRT(SUMSQ(J12,J14)) -> 2.5025587 | M13: =(Masses!B17-Masses!B15)/K13 -> 0.58043567 | N13: =M13*L13/K13 -> 0.84312595 | O13: =(Masses!I17-Masses!I15)/K13 -> 0.17158823 | P13: =O13*L13/K13 -> 0.24924465 | Q13: =Masses!K16 -> 1.2253343 | AE13: X factor | AG13: g cm-2 y-1
I14: =AVERAGE(C13,C15) -> 7.2073513 | J14: =SQRT(SUMSQ(D13,D15))/2 -> 1.770387 | AE14: =SLOPE(B5:B43,Q5:Q43) -> -0.26059607 | AG14: =-Constants!$B$25/AE14 -> 0.1196515
A15: =Masses!C18 -> 5.5 | B15: =Concentrations!O15 -> 2.2843686 | C15: =LN('C0 CA'!$B$13/Concentrations!G15)/Constants!$B$25 -> 8.6031966 | D15: =SQRT(F15^2+G15^2+H15^2)/Constants!$B$25 -> 2.5056023 | E15: =Constants!$B$15-CA!C15 -> 2012.9911 | F15: =Constants!$B$26*C15 -> 0.0014480636 | G15: ='C0 CA'!$C$13/'C0 CA'!$B$13 -> 0.077415386 | H15: =Concentrations!H15/Concentrations!G15 -> 0.010416547 | K15: =I16-I14 -> 1.6089969 | L15: =SQRT(SUMSQ(J14,J16)) -> 2.504815 | M15: =(Masses!B19-Masses!B17)/K15 -> 0.62150522 | N15: =M15*L15/K15 -> 0.96753173 | O15: =(Masses!I19-Masses!I17)/K15 -> 0.18318744 | P15: =O15*L15/K15 -> 0.28517807 | Q15: =Masses!K18 -> 1.5205182
I16: =AVERAGE(C15,C17) -> 8.8163482 | J16: =SQRT(SUMSQ(D15,D17))/2 -> 1.7719559
A17: =Masses!C20 -> 6.5 | B17: =Concentrations!O17 -> 2.2710761 | C17: =LN('C0 CA'!$B$13/Concentrations!G17)/Constants!$B$25 -> 9.0294998 | D17: =SQRT(F17^2+G17^2+H17^2)/Constants!$B$25 -> 2.5062459 | E17: =Constants!$B$15-CA!C17 -> 2012.5648 | F17: =Constants!$B$26*C17 -> 0.0015198176 | G17: ='C0 CA'!$C$13/'C0 CA'!$B$13 -> 0.077415386 | H17: =Concentrations!H17/Concentrations!G17 -> 0.010555933 | K17: =I18-I16 -> 2.3303282 | L17: =SQRT(SUMSQ(J16,J18)) -> 2.5079491 | M17: =(Masses!B21-Masses!B19)/K17 -> 0.4291241 | N17: =M17*L17/K17 -> 0.46183254 | O17: =(Masses!I21-Masses!I19)/K17 -> 0.12406154 | P17: =O17*L17/K17 -> 0.13351768 | Q17: =Masses!K20 -> 1.8124443
I18: =AVERAGE(C17,C19) -> 11.146676 | J18: =SQRT(SUMSQ(D17,D19))/2 -> 1.7748186
A19: =Masses!C22 -> 7.5 | B19: =Concentrations!O19 -> 2.139046 | C19: =LN('C0 CA'!$B$13/Concentrations!G19)/Constants!$B$25 -> 13.263853 | D19: =SQRT(F19^2+G19^2+H19^2)/Constants!$B$25 -> 2.5136935 | E19: =Constants!$B$15-CA!C19 -> 2008.3304 | F19: =Constants!$B$26*C19 -> 0.0022325309 | G19: ='C0 CA'!$C$13/'C0 CA'!$B$13 -> 0.077415386 | H19: =Concentrations!H19/Concentrations!G19 -> 0.012045827 | K19: =I20-I18 -> 7.406003 | L19: =SQRT(SUMSQ(J18,J20)) -> 2.5193293 | M19: =(Masses!B23-Masses!B21)/K19 -> 0.1350256 | N19: =M19*L19/K19 -> 0.04593219 | O19: =(Masses!I23-Masses!I21)/K19 -> 0.03817413 | P19: =O19*L19/K19 -> 0.012985844 | Q19: =Masses!K22 -> 2.0983552
I20: =AVERAGE(C19,C21) -> 18.552679 | J20: =SQRT(SUMSQ(D19,D21))/2 -> 1.7880266
A21: =Masses!C24 -> 8.5 | B21: =Concentrations!O21 -> 1.8092273 | C21: =LN('C0 CA'!$B$13/Concentrations!G21)/Constants!$B$25 -> 23.841506 | D21: =SQRT(F21^2+G21^2+H21^2)/Constants!$B$25 -> 2.5435214 | E21: =Constants!$B$15-CA!C21 -> 1997.7528 | F21: =Constants!$B$26*C21 -> 0.0040129289 | G21: ='C0 CA'!$C$13/'C0 CA'!$B$13 -> 0.077415386 | H21: =Concentrations!H21/Concentrations!G21 -> 0.016752326 | K21: =I22-I20 -> 5.1711958 | L21: =SQRT(SUMSQ(J20,J22)) -> 2.535874 | M21: =(Masses!B25-Masses!B23)/K21 -> 0.19337887 | N21: =M21*L21/K21 -> 0.094829993 | O21: =(Masses!I25-Masses!I23)/K21 -> 0.054825964 | P21: =O21*L21/K21 -> 0.026885801 | Q21: =Masses!K24 -> 2.381472
I22: =AVERAGE(C21,C23) -> 23.723875 | J22: =SQRT(SUMSQ(D21,D23))/2 -> 1.7982264
A23: =Masses!C26 -> 9.5 | B23: =Concentrations!O23 -> 1.8165629 | C23: =LN('C0 CA'!$B$13/Concentrations!G23)/Constants!$B$25 -> 23.606245 | D23: =SQRT(F23^2+G23^2+H23^2)/Constants!$B$25 -> 2.5426309 | E23: =Constants!$B$15-CA!C23 -> 1997.988 | F23: =Constants!$B$26*C23 -> 0.0039733304 | G23: ='C0 CA'!$C$13/'C0 CA'!$B$13 -> 0.077415386 | H23: =Concentrations!H23/Concentrations!G23 -> 0.016629887 | K23: =I24-I22 -> 0.94258276 | L23: =SQRT(SUMSQ(J22,J24)) -> 2.5449793 | M23: =(Masses!B27-Masses!B25)/K23 -> 1.0609148 | N23: =M23*L23/K23 -> 2.8644765 | O23: =(Masses!I27-Masses!I25)/K23 -> 0.28009636 | P23: =O23*L23/K23 -> 0.75626191 | Q23: =Masses!K26 -> 2.6552369
I24: =AVERAGE(C23,C25) -> 24.666458 | J24: =SQRT(SUMSQ(D23,D25))/2 -> 1.8009168
A25: =Masses!C28 -> 10.5 | B25: =Concentrations!O25 -> 1.7504465 | C25: =LN('C0 CA'!$B$13/Concentrations!G25)/Constants!$B$25 -> 25.726671 | D25: =SQRT(F25^2+G25^2+H25^2)/Constants!$B$25 -> 2.551124 | E25: =Constants!$B$15-CA!C25 -> 1995.8676 | F25: =Constants!$B$26*C25 -> 0.0043302342 | G25: ='C0 CA'!$C$13/'C0 CA'!$B$13 -> 0.077415386 | H25: =Concentrations!H25/Concentrations!G25 -> 0.017766559 | K25: =I26-I24 -> 4.974678 | L25: =SQRT(SUMSQ(J24,J26)) -> 2.5596654 | M25: =(Masses!B29-Masses!B27)/K25 -> 0.20101804 | N25: =M25*L25/K25 -> 0.1034316 | O25: =(Masses!I29-Masses!I27)/K25 -> 0.05411577 | P25: =O25*L25/K25 -> 0.027844669 | Q25: =Masses!K28 -> 2.9218481
I26: =AVERAGE(C25,C27) -> 29.641136 | J26: =SQRT(SUMSQ(D25,D27))/2 -> 1.8189518
A27: =Masses!C30 -> 11.5 | B27: =Concentrations!O27 -> 1.5063349 | C27: =LN('C0 CA'!$B$13/Concentrations!G27)/Constants!$B$25 -> 33.555601 | D27: =SQRT(F27^2+G27^2+H27^2)/Constants!$B$25 -> 2.5934741 | E27: =Constants!$B$15-CA!C27 -> 1988.0387 | F27: =Constants!$B$26*C27 -> 0.0056479754 | G27: ='C0 CA'!$C$13/'C0 CA'!$B$13 -> 0.077415386 | H27: =Concentrations!H27/Concentrations!G27 -> 0.022678785 | K27: =I28-I26 -> 4.0827224 | L27: =SQRT(SUMSQ(J26,J28)) -> 2.5835266 | M27: =(Masses!B31-Masses!B29)/K27 -> 0.2449346 | N27: =M27*L27/K27 -> 0.15499341 | O27: =(Masses!I31-Masses!I29)/K27 -> 0.062008375 | P27: =O27*L27/K27 -> 0.039238594 | Q27: =Masses!K30 -> 3.1830339
I28: =AVERAGE(C27,C29) -> 33.723858 | J28: =SQRT(SUMSQ(D27,D29))/2 -> 1.8346728
A29: =Masses!C32 -> 12.5 | B29: =Concentrations!O29 -> 1.4958421 | C29: =LN('C0 CA'!$B$13/Concentrations!G29)/Constants!$B$25 -> 33.892116 | D29: =SQRT(F29^2+G29^2+H29^2)/Constants!$B$25 -> 2.5957636 | E29: =Constants!$B$15-CA!C29 -> 1987.7022 | F29: =Constants!$B$26*C29 -> 0.0057046167 | G29: ='C0 CA'!$C$13/'C0 CA'!$B$13 -> 0.077415386 | H29: =Concentrations!H29/Concentrations!G29 -> 0.022918007 | K29: =I30-I28 -> -2.1709874 | L29: =SQRT(SUMSQ(J28,J30)) -> 2.588183 | M29: =(Masses!B33-Masses!B31)/K29 -> -0.46061991 | N29: =M29*L29/K29 -> 0.5491366 | O29: =(Masses!I33-Masses!I31)/K29 -> -0.12404925 | P29: =O29*L29/K29 -> 0.14788762 | Q29: =Masses!K32 -> 3.4442701
I30: =AVERAGE(C29,C31) -> 31.552871 | J30: =SQRT(SUMSQ(D29,D31))/2 -> 1.8255594
A31: =Masses!C34 -> 13.5 | B31: =Concentrations!O31 -> 1.6417207 | C31: =LN('C0 CA'!$B$13/Concentrations!G31)/Constants!$B$25 -> 29.213626 | D31: =SQRT(F31^2+G31^2+H31^2)/Constants!$B$25 -> 2.5676213 | E31: =Constants!$B$15-CA!C31 -> 1992.3807 | F31: =Constants!$B$26*C31 -> 0.0049171476 | G31: ='C0 CA'!$C$13/'C0 CA'!$B$13 -> 0.077415386 | H31: =Concentrations!H31/Concentrations!G31 -> 0.019807172 | K31: =I32-I30 -> -3.0164961 | L31: =SQRT(SUMSQ(J30,J32)) -> 2.5729889 | M31: =(Masses!B35-Masses!B33)/K31 -> -0.33151045 | N31: =M31*L31/K31 -> 0.28276938 | O31: =(Masses!I35-Masses!I33)/K31 -> -0.089390783 | P31: =O31*L31/K31 -> 0.0762479 | Q31: =Masses!K34 -> 3.7137482
I32: =AVERAGE(C31,C33) -> 28.536375 | J32: =SQRT(SUMSQ(D31,D33))/2 -> 1.8131754
A33: =Masses!C36 -> 14.5 | B33: =Concentrations!O33 -> 1.6839551 | C33: =LN('C0 CA'!$B$13/Concentrations!G33)/Constants!$B$25 -> 27.859124 | D33: =SQRT(F33^2+G33^2+H33^2)/Constants!$B$25 -> 2.5608087 | E33: =Constants!$B$15-CA!C33 -> 1993.7352 | F33: =Constants!$B$26*C33 -> 0.004689162 | G33: ='C0 CA'!$C$13/'C0 CA'!$B$13 -> 0.077415386 | H33: =Concentrations!H33/Concentrations!G33 -> 0.018988051 | K33: =I34-I32 -> 0.49541732 | L33: =SQRT(SUMSQ(J32,J34)) -> 2.5655543 | M33: =(Masses!B37-Masses!B35)/K33 -> 2.0185003 | N33: =M33*L33/K33 -> 10.452949 | O33: =(Masses!I37-Masses!I35)/K33 -> 0.55420339 | P33: =O33*L33/K33 -> 2.8699822 | Q33: =Masses!K36 -> 3.9858527
I34: =AVERAGE(C33,C35) -> 29.031792 | J34: =SQRT(SUMSQ(D33,D35))/2 -> 1.8150659
A35: =Masses!C38 -> 15.5 | B35: =Concentrations!O35 -> 1.6108258 | C35: =LN('C0 CA'!$B$13/Concentrations!G35)/Constants!$B$25 -> 30.20446 | D35: =SQRT(F35^2+G35^2+H35^2)/Constants!$B$25 -> 2.5729585 | E35: =Constants!$B$15-CA!C35 -> 1991.3898 | F35: =Constants!$B$26*C35 -> 0.0050839218 | G35: ='C0 CA'!$C$13/'C0 CA'!$B$13 -> 0.077415386 | H35: =Concentrations!H35/Concentrations!G35 -> 0.020428668 | K35: =I36-I34 -> 3.6063632 | L35: =SQRT(SUMSQ(J34,J36)) -> 2.5777691 | M35: =(Masses!B39-Masses!B37)/K35 -> 0.27728766 | N35: =M35*L35/K35 -> 0.19820066 | O35: =(Masses!I39-Masses!I37)/K35 -> 0.074150431 | P35: =O35*L35/K35 -> 0.053001509 | Q35: =Masses!K38 -> 4.2568403 | AE35: Slope | AG35: SAR
I36: =AVERAGE(C35,C37) -> 32.638155 | J36: =SQRT(SUMSQ(D35,D37))/2 -> 1.8304179 | AE36: X factor | AG36: cm y-1
A37: =Masses!C40 -> 16.5 | B37: =Concentrations!O37 -> 1.4590571 | C37: =LN('C0 CA'!$B$13/Concentrations!G37)/Constants!$B$25 -> 35.07185 | D37: =SQRT(F37^2+G37^2+H37^2)/Constants!$B$25 -> 2.6041511 | E37: =Constants!$B$15-CA!C37 -> 1986.5224 | F37: =Constants!$B$26*C37 -> 0.0059031859 | G37: ='C0 CA'!$C$13/'C0 CA'!$B$13 -> 0.077415386 | H37: =Concentrations!H37/Concentrations!G37 -> 0.023776742 | K37: =I38-I36 -> 6.0181289 | L37: =SQRT(SUMSQ(J36,J38)) -> 2.612894 | M37: =(Masses!B41-Masses!B39)/K37 -> 0.1661646 | N37: =M37*L37/K37 -> 0.072143767 | O37: =(Masses!I41-Masses!I39)/K37 -> 0.044894244 | P37: =O37*L37/K37 -> 0.019491756 | Q37: =Masses!K40 -> 4.5256367 | AE37: =SLOPE(B5:B43,A5:A43) -> -0.071799753 | AG37: =-Constants!$B$25/AE37 -> 0.43427322
I38: =AVERAGE(C37,C39) -> 38.656284 | J38: =SQRT(SUMSQ(D37,D39))/2 -> 1.864614
A39: =Masses!C42 -> 17.5 | B39: =Concentrations!O39 -> 1.2355268 | C39: =LN('C0 CA'!$B$13/Concentrations!G39)/Constants!$B$25 -> 42.240718 | D39: =SQRT(F39^2+G39^2+H39^2)/Constants!$B$25 -> 2.6693705 | E39: =Constants!$B$15-CA!C39 -> 1979.3536 | F39: =Constants!$B$26*C39 -> 0.0071098277 | G39: ='C0 CA'!$C$13/'C0 CA'!$B$13 -> 0.077415386 | H39: =Concentrations!H39/Concentrations!G39 -> 0.029732448 | K39: =I40-I38 -> 4.1851462 | L39: =SQRT(SUMSQ(J38,J40)) -> 2.6566878 | M39: =(Masses!B43-Masses!B41)/K39 -> 0.23894028 | N39: =M39*L39/K39 -> 0.15167683 | O39: =(Masses!I43-Masses!I41)/K39 -> 0.064859356 | P39: =O39*L39/K39 -> 0.041172053 | Q39: =Masses!K42 -> 4.7964493 | AI39: SAR = | AJ39: λ / slope
I40: =AVERAGE(C39,C41) -> 42.841431 | J40: =SQRT(SUMSQ(D39,D41))/2 -> 1.8924071
A41: =Masses!C44 -> 18.5 | B41: =Concentrations!O41 -> 1.1980655 | C41: =LN('C0 CA'!$B$13/Concentrations!G41)/Constants!$B$25 -> 43.442143 | D41: =SQRT(F41^2+G41^2+H41^2)/Constants!$B$25 -> 2.6831474 | E41: =Constants!$B$15-CA!C41 -> 1978.1521 | F41: =Constants!$B$26*C41 -> 0.0073120478 | G41: ='C0 CA'!$C$13/'C0 CA'!$B$13 -> 0.077415386 | H41: =Concentrations!H41/Concentrations!G41 -> 0.030867395 | K41: =I42-I40 -> 0.80695933 | L41: =SQRT(SUMSQ(J40,J42)) -> 2.6809497 | M41: =(Masses!B45-Masses!B43)/K41 -> 1.2392198 | N41: =M41*L41/K41 -> 4.1170426 | O41: =(Masses!I45-Masses!I43)/K41 -> 0.33696854 | P41: =O41*L41/K41 -> 1.1195059 | Q41: =Masses!K44 -> 5.0681322
...

Sheet CFCS
E1: t = 𝚫Z/s | M1: MAR | N1: SAR
B2: Midpoint
B3: zi | C3: mi | D3: ln Ci | E3: Time | F3: Year | G3: uncertainty
B4: (cm) | C4: (g cm-2) | E4: t | G4: t
B5: {=_xlfn._xlws.FILTER(Concentrations!A5:'Concentrations'!A74,(Concentrations!A5:'Concentrations'!A74<>""))} -> 0.5 | C5: {=_xlfn._xlws.FILTER(Concentrations!N5:'Concentrations'!N74,(Concentrations!N5:'Concentrations'!N74<>""))} -> 0.11305196 | D5: {=_xlfn._xlws.FILTER(Concentrations!O5:'Concentrations'!O74,(Concentrations!O5:'Concentrations'!O74<>""))} -> 2.4151092 | E5: =(B5-$B$5)/($N$21) -> 0 | F5: =Constants!$B$15-E5 -> 2021.5943 | G5: =E5*($N$24/$N$21) -> 0 | N5: upper linest
B6: 1.5 | C6: 0.36344807 | D6: 2.3419753 | E6: =(B6-$B$5)/($N$21) -> 2.299432 | F6: =Constants!$B$15-E6 -> 2019.2949 | G6: =E6*($N$24/$N$21) -> 0.097411408 | N6: slope | O6: {=LINEST(D5:D32,B5:B32,TRUE,TRUE)} -> -0.071697923 | P6: 2.5637646 | Q6: intercept
B7: 2.5 | C7: 0.64298113 | D7: 2.4479758 | E7: =(B7-$B$5)/($N$21) -> 4.598864 | F7: =Constants!$B$15-E7 -> 2016.9954 | G7: =E7*($N$24/$N$21) -> 0.19482282 | N7: standard error | O7: 0.0030125972 | P7: 0.048693301 | Q7: standard error
B8: 3.5 | C8: 0.93134727 | D8: 2.3918075 | E8: =(B8-$B$5)/($N$21) -> 6.898296 | F8: =Constants!$B$15-E8 -> 2014.696 | G8: =E8*($N$24/$N$21) -> 0.29223423 | N8: r square | O8: 0.95611149 | P8: 0.12876871 | Q8: r square
B9: 4.5 | C9: 1.2253343 | D9: 2.3714155 | E9: =(B9-$B$5)/($N$21) -> 9.1977281 | F9: =Constants!$B$15-E9 -> 2012.3966 | G9: =E9*($N$24/$N$21) -> 0.38964563 | N9: F | O9: 566.41012 | P9: 26 | Q9: F
B10: 5.5 | C10: 1.5205182 | D10: 2.2843686 | E10: =(B10-$B$5)/($N$21) -> 11.49716 | F10: =Constants!$B$15-E10 -> 2010.0971 | G10: =E10*($N$24/$N$21) -> 0.48705704 | N10: ss | O10: 9.3918618 | P10: 0.43111589 | Q10: ss
B11: 6.5 | C11: 1.8124443 | D11: 2.2710761 | E11: =(B11-$B$5)/($N$21) -> 13.796592 | F11: =Constants!$B$15-E11 -> 2007.7977 | G11: =E11*($N$24/$N$21) -> 0.58446845
B12: 7.5 | C12: 2.0983552 | D12: 2.139046 | E12: =(B12-$B$5)/($N$21) -> 16.096024 | F12: =Constants!$B$15-E12 -> 2005.4983 | G12: =E12*($N$24/$N$21) -> 0.68187986 | N12: lower linest
B13: 8.5 | C13: 2.381472 | D13: 1.8092273 | E13: =(B13-$B$5)/($N$21) -> 18.395456 | F13: =Constants!$B$15-E13 -> 2003.1988 | G13: =E13*($N$24/$N$21) -> 0.77929127 | N13: slope | O13: {=LINEST(D32:D39,B32:B39,TRUE,TRUE)} -> -0.27854813 | P13: 8.3426026 | Q13: intercept
B14: 9.5 | C14: 2.6552369 | D14: 1.8165629 | E14: =(B14-$B$5)/($N$21) -> 20.694888 | F14: =Constants!$B$15-E14 -> 2000.8994 | G14: =E14*($N$24/$N$21) -> 0.87670268 | N14: standard error | O14: 0.019903774 | P14: 0.61870009 | Q14: standard error
B15: 10.5 | C15: 2.9218481 | D15: 1.7504465 | E15: =(B15-$B$5)/($N$21) -> 22.99432 | F15: =Constants!$B$15-E15 -> 1998.6 | G15: =E15*($N$24/$N$21) -> 0.97411408 | N15: r square | O15: 0.97027536 | P15: 0.1289912 | Q15: r square
B16: 11.5 | C16: 3.1830339 | D16: 1.5063349 | E16: =(B16-$B$5)/($N$21) -> 25.293752 | F16: =Constants!$B$15-E16 -> 1996.3005 | G16: =E16*($N$24/$N$21) -> 1.0715255 | N16: F | O16: 195.85274 | P16: 6 | Q16: F
B17: 12.5 | C17: 3.4442701 | D17: 1.4958421 | E17: =(B17-$B$5)/($N$21) -> 27.593184 | F17: =Constants!$B$15-E17 -> 1994.0011 | G17: =E17*($N$24/$N$21) -> 1.1689369 | N17: ss | O17: 3.2587405 | P17: 0.099832371 | Q17: ss
B18: 13.5 | C18: 3.7137482 | D18: 1.6417207 | E18: =(B18-$B$5)/($N$21) -> 29.892616 | F18: =Constants!$B$15-E18 -> 1991.7017 | G18: =E18*($N$24/$N$21) -> 1.2663483
B19: 14.5 | C19: 3.9858527 | D19: 1.6839551 | E19: =(B19-$B$5)/($N$21) -> 32.192048 | F19: =Constants!$B$15-E19 -> 1989.4022 | G19: =E19*($N$24/$N$21) -> 1.3637597
B20: 15.5 | C20: 4.2568403 | D20: 1.6108258 | E20: =(B20-$B$5)/($N$21) -> 34.49148 | F20: =Constants!$B$15-E20 -> 1987.1028 | G20: =E20*($N$24/$N$21) -> 1.4611711 | N20: upper SAR | O20: lower SAR
B21: 16.5 | C21: 4.5256367 | D21: 1.4590571 | E21: =(B21-$B$5)/($N$21) -> 36.790912 | F21: =Constants!$B$15-E21 -> 1984.8034 | G21: =E21*($N$24/$N$21) -> 1.5585825 | N21: =-Constants!$B$25/O6 -> 0.43489 | O21: =-Constants!$B$25/O13 -> 0.11194012 | P21: cm/yr
B22: 17.5 | C22: 4.7964493 | D22: 1.2355268 | E22: =(B22-$B$5)/($N$21) -> 39.090344 | F22: =Constants!$B$15-E22 -> 1982.5039 | G22: =E22*($N$24/$N$21) -> 1.6559939
B23: 18.5 | C23: 5.0681322 | D23: 1.1980655 | E23: =(B23-$B$5)/($N$21) -> 41.389776 | F23: =Constants!$B$15-E23 -> 1980.2045 | G23: =E23*($N$24/$N$21) -> 1.7534054 | N23: uncert. | O23: uncert.
B24: 19.5 | C24: 5.3380711 | D24: 1.1852036 | E24: =(B24-$B$5)/($N$21) -> 43.689208 | F24: =Constants!$B$15-E24 -> 1977.9051 | G24: =E24*($N$24/$N$21) -> 1.8508168 | N24: =N21*SQRT((-O7/O6)^2+(Constants!B26/Constants!B25)^2) -> 0.018423353 | O24: =O21*SQRT((-O14/O13)^2+(Constants!B26/Constants!B25)^2) -> 0.0080215203 | P24: cm/yr
B25: 20.5 | C25: 5.6348202 | D25: 0.86243027 | E25: =(B25-$B$5)/($N$21) -> 45.98864 | F25: =Constants!$B$15-E25 -> 1975.6056 | G25: =E25*($N$24/$N$21) -> 1.9482282
B26: 21.5 | C26: 5.9607994 | D26: 0.82439434 | E26: =(B26-$B$5)/($N$21) -> 48.288072 | F26: =Constants!$B$15-E26 -> 1973.3062 | G26: =E26*($N$24/$N$21) -> 2.0456396
B27: 22.5 | C27: 6.2904518 | D27: 0.92066945 | E27: =(B27-$B$5)/($N$21) -> 50.587504 | F27: =Constants!$B$15-E27 -> 1971.0068 | G27: =E27*($N$24/$N$21) -> 2.143051
B28: 23.5 | C28: 6.6224317 | D28: 1.0692578 | E28: =(B28-$B$5)/($N$21) -> 52.886936 | F28: =Constants!$B$15-E28 -> 1968.7073 | G28: =E28*($N$24/$N$21) -> 2.2404624
B29: 24.5 | C29: 6.938891 | D29: 0.77966153 | E29: =(B29-$B$5)/($N$21) -> 55.186368 | F29: =Constants!$B$15-E29 -> 1966.4079 | G29: =E29*($N$24/$N$21) -> 2.3378738
B30: 25.5 | C30: 7.2464829 | D30: 0.76053002 | E30: =(B30-$B$5)/($N$21) -> 57.4858 | F30: =Constants!$B$15-E30 -> 1964.1085 | G30: =E30*($N$24/$N$21) -> 2.4352852
B31: 26.5 | C31: 7.5534927 | D31: 0.7270848 | E31: =(B31-$B$5)/($N$21) -> 59.785232 | F31: =Constants!$B$15-E31 -> 1961.8091 | G31: =E31*($N$24/$N$21) -> 2.5326966
B32: 27.5 | C32: 7.8596959 | D32: 0.6802522 | E32: =(B32-$B$31)/($O$21)+$E$31 -> 68.71858 | F32: =Constants!$B$15-E32 -> 1952.8757 | G32: =E32*($O$24/$O$21) -> 4.9243069
B33: 28.5 | C33: 8.1673303 | D33: 0.23919972 | E33: =(B33-$B$31)/($O$21)+$E$31 -> 77.651928 | F33: =Constants!$B$15-E33 -> 1943.9424 | G33: =E33*($O$24/$O$21) -> 5.5644619
B34: 29.5 | C34: 8.4825684 | D34: 0.1224161 | E34: =(B34-$B$31)/($O$21)+$E$31 -> 86.585276 | F34: =Constants!$B$15-E34 -> 1935.009 | G34: =E34*($O$24/$O$21) -> 6.204617
B35: 30.5 | C35: 8.8118726 | D35: 0.036684865 | E35: =(B35-$B$31)/($O$21)+$E$31 -> 95.518624 | F35: =Constants!$B$15-E35 -> 1926.0757 | G35: =E35*($O$24/$O$21) -> 6.844772
B36: 31.5 | C36: 9.1283871 | D36: -0.41453632 | E36: =(B36-$B$31)/($O$21)+$E$31 -> 104.45197 | F36: =Constants!$B$15-E36 -> 1917.1423 | G36: =E36*($O$24/$O$21) -> 7.4849271
B37: 32.5 | C37: 9.4312573 | D37: -0.56884076 | E37: =(B37-$B$31)/($O$21)+$E$31 -> 113.38532 | F37: =Constants!$B$15-E37 -> 1908.209 | G37: =E37*($O$24/$O$21) -> 8.1250821
B38: 33.5 | C38: 9.7299206 | D38: -1.0623748 | E38: =(B38-$B$31)/($O$21)+$E$31 -> 122.31867 | F38: =Constants!$B$15-E38 -> 1899.2756 | G38: =E38*($O$24/$O$21) -> 8.7652372
B39: 34.5 | C39: 10.028167 | D39: -1.3719161 | E39: =(B39-$B$31)/($O$21)+$E$31 -> 131.25202 | F39: =Constants!$B$15-E39 -> 1890.3423 | G39: =E39*($O$24/$O$21) -> 9.4053922
B42: upper linest | G42: lower linest
...

Sheet DBD(0)
G2: LINEST
F3: slope | G3: {=LINEST(C18:C20,B18:B20,TRUE,TRUE)} -> 0.10851095 | H3: 0.22123136 | I3: intercept
F4: Std. err slope | G4: 0.045819964 | H4: 0.019766416 | I4: Std. err. Intercept
F5: r2 | G5: 0.84867705 | H5: 0.017178146 | I5: s(y)
F6: F | G6: 5.6083827 | H6: 1 | I6: degrees of freedom
F7: regression ss | G7: 0.0016549703 | H7: 0.00029508869 | I7: residual ss
B9: Coefficients | C9: Std Error
A10: Intercept | B10: =INTERCEPT(C18:C20,B18:B20) -> 0.22123136 | C10: =H4 -> 0.019766416
A11: X Variable 1 | B11: =SLOPE(C18:C20,B18:B20) -> 0.10851095 | C11: =G4 -> 0.045819964
A13: DBD | B13: =B10 -> 0.22123136 | C13: =C10 -> 0.019766416
A16: zi | B16: mi | C16: DBD
A17: (cm) | B17: (g cm-2)
A18: {=_xlfn._xlws.FILTER(Concentrations!A5:'Concentrations'!A24,(Concentrations!A5:'Concentrations'!A24<>""))} -> 0.5 | B18: {=_xlfn._xlws.FILTER(Concentrations!N5:'Concentrations'!N24,(Concentrations!N5:'Concentrations'!N24<>""))} -> 0.11305196 | C18: {=_xlfn._xlws.FILTER(Masses!E8:'Masses'!E26,(Masses!E8:'Masses'!E26<>""))} -> 0.22610392
A19: 1.5 | B19: 0.36344807 | C19: 0.27468829
A20: 2.5 | B20: 0.64298113 | C20: 0.28437784
A21: 3.5 | B21: 0.93134727 | C21: 0.29235443
A22: 4.5 | B22: 1.2253343 | C22: 0.29561971
A23: 5.5 | B23: 1.5205182 | C23: 0.29474803
A24: 6.5 | B24: 1.8124443 | C24: 0.28910411
A25: 7.5 | B25: 2.0983552 | C25: 0.28271773
A26: 8.5 | B26: 2.381472 | C26: 0.28351579
A27: 9.5 | B27: 2.6552369 | C27: 0.264014

Sheet CF
G1: ln (A(0)/A(i)/𝛌 | J1: 𝛌A(0)/C0 | L1: Masses E | P1: r(i)/𝛒(i)
B2: Layer | C2: Inventory | E2: Inventory | G2: age | J2: MAR | L2: DBD | N2: DBD | P2: SAR
E3: Below | L3: section | N3: layer | Y3: z(i) | Z3: Depth of layer
A4: middle of | B4: =Masses!B5 -> z(i) | C4: ΔAi | D4: u(ΔAi) | E4: A(i) | F4: u(A(i)) | G4: t(i) | H4: u(t(i)) | I4: Year | J4: r(i) | K4: u(r(i)) | L4: ri | M4: u(ri) | N4: r(i) | O4: u(r(i)) | P4: s(i) | Q4: u(s(i)) | T4: r | W4: S | Y4: ΔAi | Z4: Pb-210ex deposit in section
A5: Inverval (cm) | B5: (cm) | C5: (dpm cm-2) | E5: (dpm cm-2) | G5: (yr) | H5: (yr) | I5: (A.D.) | J5: (g cm-2 yr-1) | L5: (g cm-3) | N5: (g cm-3) | P5: (cm yr-1) | T5: (g m-2 yr-1) | U5: fraction C | V5: C MAR | W5: SAR | X5: Year | Y5: u(ΔAi)
B6: =Masses!B7 -> 0 | E6: =E8+C7 -> 46.283722 | F6: =SQRT(SUMSQ(F8,D7)) -> 0.26735443 | G6: =LN($E$6/E6)/Constants!$B$25 -> 0 | H6: =SQRT((G6*Constants!$B$26)^2+($F$6/$E$6)^2+(1-2*E6/$E$6)*(F6/E6)^2)/Constants!$B$25 -> 0 | I6: =Constants!$B$15-G6 -> 2021.5943 | J6: =Constants!$B$25*CF!E6/Concentrations!I4 -> 0.11238917 | K6: =J6*SQRT((F6/E6)^2+(1-(E6-E8)/(E6))*(Concentrations!J4/Concentrations!I4)^2) -> 0.0084843514 | N6: ='DBD(0)'!B13 -> 0.22123136 | O6: ='DBD(0)'!C13 -> 0.019766416 | P6: =J6/N6 -> 0.50801647 | Q6: =P6*SQRT(SUMSQ(K6/J6,O6/N6)) -> 0.059422287 | T6: =J6*10000 -> 1123.8917 | V6: =(T6)*(U6) -> 0 | W6: =P6 -> 0.50801647 | X6: =I6 -> 2021.5943 | Y6: A(i) | Z6: Accumulated deposit below layer
A7: =Masses!C8 -> 0.5 | C7: =Concentrations!K5 -> 2.5303272 | D7: =Concentrations!L5 -> 0.058956529 | L7: =Masses!E8 -> 0.22610392 | M7: =Masses!H8 -> 0.0048459592 | Y7: u(A(i))
B8: =Masses!B9 -> 1 | E8: =E10+C9 -> 43.753395 | F8: =SQRT(SUMSQ(F10,D9)) -> 0.26077292 | G8: =LN($E$6/E8)/Constants!$B$25 -> 1.8030737 | H8: =SQRT((G8*Constants!$B$26)^2+($F$6/$E$6)^2+(1-2*E8/$E$6)*(F8/E8)^2)/Constants!$B$25 -> 0.043276494 | I8: =Constants!$B$15-G8 -> 2019.7912 | J8: =Constants!$B$25*CF!E8/Concentrations!I6 -> 0.12636293 | K8: =J8*SQRT((F8/E8)^2+(1-(E8-E10)/(E8))*(Concentrations!J6/Concentrations!I6)^2) -> 0.0011122103 | N8: =AVERAGE(L7,L9) -> 0.25039611 | O8: =SQRT((M7^2+M9^2))/2 -> 0.0032461928 | P8: =J8/N8 -> 0.50465214 | Q8: =P8*SQRT(SUMSQ(K8/J8,O8/N8)) -> 0.0079077787 | T8: =J8*10000 -> 1263.6293 | V8: =(T8)*(U8) -> 0 | W8: =P8 -> 0.50465214 | X8: =I8 -> 2019.7912 | Y8: t(i) | Z8: Time elapsed since formation of layer | AO8: Inventory = Interval Thickness* XS Pb-210*DBD
A9: =Masses!C10 -> 1.5 | C9: =Concentrations!K7 -> 2.8572425 | D9: =Concentrations!L7 -> 0.053001915 | L9: =Masses!E10 -> 0.27468829 | M9: =Masses!H10 -> 0.004320619 | Y9: u(t(i))
B10: =Masses!B11 -> 2 | E10: =E12+C11 -> 40.896152 | F10: =SQRT(SUMSQ(F12,D11)) -> 0.25532982 | G10: =LN($E$6/E10)/Constants!$B$25 -> 3.9689391 | H10: =SQRT((G10*Constants!$B$26)^2+($F$6/$E$6)^2+(1-2*E10/$E$6)*(F10/E10)^2)/Constants!$B$25 -> 0.063403519 | I10: =Constants!$B$15-G10 -> 2017.6253 | J10: =Constants!$B$25*CF!E10/Concentrations!I8 -> 0.1161005 | K10: =J10*SQRT((F10/E10)^2+(1-(E10-E12)/(E10))*(Concentrations!J8/Concentrations!I8)^2) -> 0.0010309836 | N10: =AVERAGE(L9,L11) -> 0.27953306 | O10: =SQRT((M9^2+M11^2))/2 -> 0.003167993 | P10: =J10/N10 -> 0.41533727 | Q10: =P10*SQRT(SUMSQ(K10/J10,O10/N10)) -> 0.0059799429 | T10: =J10*10000 -> 1161.005 | V10: =(T10)*(U10) -> 0 | W10: =P10 -> 0.41533727 | X10: =I10 -> 2017.6253 | Y10: Year | Z10: Date of deposition of layer | AO10: Age = LN (total inverntory/Inventory below the layer)/decay constant
A11: =Masses!C12 -> 2.5 | C11: =Concentrations!K9 -> 3.2888051 | D11: =Concentrations!L9 -> 0.060980118 | L11: =Masses!E12 -> 0.28437784 | M11: =Masses!H12 -> 0.0046343253 | Y11: r(i) | Z11: Mass accumulation rate of layer - MAR
B12: =Masses!B13 -> 3 | E12: =E14+C13 -> 37.607347 | F12: =SQRT(SUMSQ(F14,D13)) -> 0.247941 | G12: =LN($E$6/E12)/Constants!$B$25 -> 6.6576703 | H12: =SQRT((G12*Constants!$B$26)^2+($F$6/$E$6)^2+(1-2*E12/$E$6)*(F12/E12)^2)/Constants!$B$25 -> 0.087554988 | I12: =Constants!$B$15-G12 -> 2014.9366 | J12: =Constants!$B$25*CF!E12/Concentrations!I10 -> 0.10424179 | K12: =J12*SQRT((F12/E12)^2+(1-(E12-E14)/(E12))*(Concentrations!J10/Concentrations!I10)^2) -> 0.00093986399 | N12: =AVERAGE(L11,L13) -> 0.28836613 | O12: =SQRT((M11^2+M13^2))/2 -> 0.0032899199 | P12: =J12/N12 -> 0.36149109 | Q12: =P12*SQRT(SUMSQ(K12/J12,O12/N12)) -> 0.0052565963 | T12: =J12*10000 -> 1042.4179 | V12: =(T12)*(U12) -> 0 | W12: =P12 -> 0.36149109 | X12: =I12 -> 2014.9366 | Y12: u(r(i)) | AO12: MAR = Decay constant * Inventory/ C0
A13: =Masses!C14 -> 3.5 | C13: =Concentrations!K11 -> 3.1963807 | D13: =Concentrations!L11 -> 0.059179121 | L13: =Masses!E14 -> 0.29235443 | M13: =Masses!H14 -> 0.0046709014 | Y13: ri | Z13: Dry bulk density of section
B14: =Masses!B15 -> 4 | E14: =E16+C15 -> 34.410967 | F14: =SQRT(SUMSQ(F16,D15)) -> 0.24077494 | G14: =LN($E$6/E14)/Constants!$B$25 -> 9.5063587 | H14: =SQRT((G14*Constants!$B$26)^2+($F$6/$E$6)^2+(1-2*E14/$E$6)*(F14/E14)^2)/Constants!$B$25 -> 0.11149768 | I14: =Constants!$B$15-G14 -> 2012.0879 | J14: =Constants!$B$25*CF!E14/Concentrations!I12 -> 0.099137866 | K14: =J14*SQRT((F14/E14)^2+(1-(E14-E16)/(E14))*(Concentrations!J12/Concentrations!I12)^2) -> 0.00093792777 | N14: =AVERAGE(L13,L15) -> 0.29398707 | O14: =SQRT((M13^2+M15^2))/2 -> 0.0032917768 | P14: =J14/N14 -> 0.33721845 | Q14: =P14*SQRT(SUMSQ(K14/J14,O14/N14)) -> 0.0049432202 | T14: =J14*10000 -> 991.37866 | V14: =(T14)*(U14) -> 0 | W14: =P14 -> 0.33721845 | X14: =I14 -> 2012.0879 | Y14: u(ri)
A15: =Masses!C16 -> 4.5 | C15: =Concentrations!K13 -> 3.1668394 | D15: =Concentrations!L13 -> 0.058177175 | L15: =Masses!E16 -> 0.29561971 | M15: =Masses!H16 -> 0.0046395966 | Y15: r(i) | Z15: Dry bulk density of layer | AO15: 𝛒i is DBD / interval thickness
B16: =Masses!B17 -> 5 | E16: =E18+C17 -> 31.244127 | F16: =SQRT(SUMSQ(F18,D17)) -> 0.23364073 | G16: =LN($E$6/E16)/Constants!$B$25 -> 12.602628 | H16: =SQRT((G16*Constants!$B$26)^2+($F$6/$E$6)^2+(1-2*E16/$E$6)*(F16/E16)^2)/Constants!$B$25 -> 0.13715308 | I16: =Constants!$B$15-G16 -> 2008.9917 | J16: =Constants!$B$25*CF!E16/Concentrations!I14 -> 0.094897011 | K16: =J16*SQRT((F16/E16)^2+(1-(E16-E18)/(E16))*(Concentrations!J14/Concentrations!I14)^2) -> 0.00095349797 | N16: =AVERAGE(L15,L17) -> 0.29518387 | O16: =SQRT((M15^2+M17^2))/2 -> 0.0033246938 | P16: =J16/N16 -> 0.3214844 | Q16: =P16*SQRT(SUMSQ(K16/J16,O16/N16)) -> 0.0048523339 | T16: =J16*10000 -> 948.97011 | V16: =(T16)*(U16) -> 0 | W16: =P16 -> 0.3214844 | X16: =I16 -> 2008.9917 | Y16: u(r(i))
A17: =Masses!C18 -> 5.5 | C17: =Concentrations!K15 -> 2.8942735 | D17: =Concentrations!L15 -> 0.05564709 | L17: =Masses!E18 -> 0.29474803 | M17: =Masses!H18 -> 0.0047632445 | Y17: s(i) | Z17: Sediment accumulation rate of layer - SAR | AO17: SAR = MAR/ DBD
B18: =Masses!B19 -> 6 | E18: =E20+C19 -> 28.349854 | F18: =SQRT(SUMSQ(F20,D19)) -> 0.22691714 | G18: =LN($E$6/E18)/Constants!$B$25 -> 15.720247 | H18: =SQRT((G18*Constants!$B$26)^2+($F$6/$E$6)^2+(1-2*E18/$E$6)*(F18/E18)^2)/Constants!$B$25 -> 0.16337487 | I18: =Constants!$B$15-G18 -> 2005.874 | J18: =Constants!$B$25*CF!E18/Concentrations!I16 -> 0.090620194 | K18: =J18*SQRT((F18/E18)^2+(1-(E18-E20)/(E18))*(Concentrations!J16/Concentrations!I16)^2) -> 0.00096590315 | N18: =AVERAGE(L17,L19) -> 0.29192607 | O18: =SQRT((M17^2+M19^2))/2 -> 0.0034009099 | P18: =J18/N18 -> 0.31042172 | Q18: =P18*SQRT(SUMSQ(K18/J18,O18/N18)) -> 0.0049016206 | T18: =J18*10000 -> 906.20194 | V18: =(T18)*(U18) -> 0 | W18: =P18 -> 0.31042172 | X18: =I18 -> 2005.874 | Y18: u(s(i))
A19: =Masses!C20 -> 6.5 | C19: =Concentrations!K17 -> 2.8013675 | D19: =Concentrations!L17 -> 0.055570534 | L19: =Masses!E20 -> 0.28910411 | M19: =Masses!H20 -> 0.0048555386
B20: =Masses!B21 -> 7 | E20: =E22+C21 -> 25.548486 | F20: =SQRT(SUMSQ(F22,D21)) -> 0.22000751 | G20: =LN($E$6/E20)/Constants!$B$25 -> 19.057047 | H20: =SQRT((G20*Constants!$B$26)^2+($F$6/$E$6)^2+(1-2*E20/$E$6)*(F20/E20)^2)/Constants!$B$25 -> 0.19227733 | I20: =Constants!$B$15-G20 -> 2002.5372 | J20: =Constants!$B$25*CF!E20/Concentrations!I18 -> 0.087631387 | K20: =J20*SQRT((F20/E20)^2+(1-(E20-E22)/(E20))*(Concentrations!J18/Concentrations!I18)^2) -> 0.0010049332 | N20: =AVERAGE(L19,L21) -> 0.28591092 | O20: =SQRT((M19^2+M21^2))/2 -> 0.0034421265 | P20: =J20/N20 -> 0.30649892 | Q20: =P20*SQRT(SUMSQ(K20/J20,O20/N20)) -> 0.0050960934 | T20: =J20*10000 -> 876.31387 | V20: =(T20)*(U20) -> 0 | W20: =P20 -> 0.30649892 | X20: =I20 -> 2002.5372
A21: =Masses!C22 -> 7.5 | C21: =Concentrations!K19 -> 2.4006503 | D21: =Concentrations!L19 -> 0.050532052 | L21: =Masses!E22 -> 0.28271773 | M21: =Masses!H22 -> 0.0048802341
B22: =Masses!B23 -> 8 | E22: =E24+C23 -> 23.147836 | F22: =SQRT(SUMSQ(F24,D23)) -> 0.2141257 | G22: =LN($E$6/E22)/Constants!$B$25 -> 22.221721 | H22: =SQRT((G22*Constants!$B$26)^2+($F$6/$E$6)^2+(1-2*E22/$E$6)*(F22/E22)^2)/Constants!$B$25 -> 0.2206501 | I22: =Constants!$B$15-G22 -> 1999.3726 | J22: =Constants!$B$25*CF!E22/Concentrations!I20 -> 0.09889196 | K22: =J22*SQRT((F22/E22)^2+(1-(E22-E24)/(E22))*(Concentrations!J20/Concentrations!I20)^2) -> 0.0013135444 | N22: =AVERAGE(L21,L23) -> 0.28311676 | O22: =SQRT((M21^2+M23^2))/2 -> 0.0034546374 | P22: =J22/N22 -> 0.34929744 | Q22: =P22*SQRT(SUMSQ(K22/J22,O22/N22)) -> 0.0063001567 | T22: =J22*10000 -> 988.9196 | V22: =(T22)*(U22) -> 0 | W22: =P22 -> 0.34929744 | X22: =I22 -> 1999.3726
A23: =Masses!C24 -> 8.5 | C23: =Concentrations!K21 -> 1.7310702 | D23: =Concentrations!L21 -> 0.04162638 | L23: =Masses!E24 -> 0.28351579 | M23: =Masses!H24 -> 0.0048909502
B24: =Masses!B25 -> 9 | E24: =E26+C25 -> 21.416766 | F24: =SQRT(SUMSQ(F26,D25)) -> 0.21004062 | G24: =LN($E$6/E24)/Constants!$B$25 -> 24.71452 | H24: =SQRT((G24*Constants!$B$26)^2+($F$6/$E$6)^2+(1-2*E24/$E$6)*(F24/E24)^2)/Constants!$B$25 -> 0.24391239 | I24: =Constants!$B$15-G24 -> 1996.8798 | J24: =Constants!$B$25*CF!E24/Concentrations!I22 -> 0.10896992 | K24: =J24*SQRT((F24/E24)^2+(1-(E24-E26)/(E24))*(Concentrations!J22/Concentrations!I22)^2) -> 0.0016342379 | N24: =AVERAGE(L23,L25) -> 0.2737649 | O24: =SQRT((M23^2+M25^2))/2 -> 0.0034507519 | P24: =J24/N24 -> 0.39804198 | Q24: =P24*SQRT(SUMSQ(K24/J24,O24/N24)) -> 0.0077979197 | T24: =J24*10000 -> 1089.6992 | V24: =(T24)*(U24) -> 0 | W24: =P24 -> 0.39804198 | X24: =I24 -> 1996.8798 | AB24: Carbon | AC24: Accumulation | AD24: Rate
A25: =Masses!C26 -> 9.5 | C25: =Concentrations!K23 -> 1.623866 | D25: =Concentrations!L23 -> 0.040326174 | L25: =Masses!E26 -> 0.264014 | M25: =Masses!H26 -> 0.004869226
B26: =Masses!B27 -> 10 | E26: =E28+C27 -> 19.7929 | F26: =SQRT(SUMSQ(F28,D27)) -> 0.20613312 | G26: =LN($E$6/E26)/Constants!$B$25 -> 27.243352 | H26: =SQRT((G26*Constants!$B$26)^2+($F$6/$E$6)^2+(1-2*E26/$E$6)*(F26/E26)^2)/Constants!$B$25 -> 0.26849866 | I26: =Constants!$B$15-G26 -> 1994.3509 | J26: =Constants!$B$25*CF!E26/Concentrations!I24 -> 0.1036554 | K26: =J26*SQRT((F26/E26)^2+(1-(E26-E28)/(E26))*(Concentrations!J24/Concentrations!I24)^2) -> 0.0016207184 | N26: =AVERAGE(L25,L27) -> 0.26661127 | O26: =SQRT((M25^2+M27^2))/2 -> 0.0034476418 | P26: =J26/N26 -> 0.38878851 | Q26: =P26*SQRT(SUMSQ(K26/J26,O26/N26)) -> 0.0078886026 | T26: =J26*10000 -> 1036.554 | V26: =(T26)*(U26) -> 0 | W26: =P26 -> 0.38878851 | X26: =I26 -> 1994.3509
A27: =Masses!C28 -> 10.5 | C27: =Concentrations!K25 -> 1.5498799 | D27: =Concentrations!L25 -> 0.039347987 | L27: =Masses!E28 -> 0.26920853 | M27: =Masses!H28 -> 0.0048821689
B28: =Masses!B29 -> 11 | E28: =E30+C29 -> 18.24302 | F28: =SQRT(SUMSQ(F30,D29)) -> 0.20234277 | G28: =LN($E$6/E28)/Constants!$B$25 -> 29.858454 | H28: =SQRT((G28*Constants!$B$26)^2+($F$6/$E$6)^2+(1-2*E28/$E$6)*(F28/E28)^2)/Constants!$B$25 -> 0.29510081 | I28: =Constants!$B$15-G28 -> 1991.7358 | J28: =Constants!$B$25*CF!E28/Concentrations!I26 -> 0.1108038 | K28: =J28*SQRT((F28/E28)^2+(1-(E28-E30)/(E28))*(Concentrations!J26/Concentrations!I26)^2) -> 0.0019480328 | N28: =AVERAGE(L27,L29) -> 0.26118576 | O28: =SQRT((M27^2+M29^2))/2 -> 0.0034788696 | P28: =J28/N28 -> 0.42423371 | Q28: =P28*SQRT(SUMSQ(K28/J28,O28/N28)) -> 0.0093571997 | T28: =J28*10000 -> 1108.038 | V28: =(T28)*(U28) -> 0 | W28: =P28 -> 0.42423371 | X28: =I28 -> 1991.7358
A29: =Masses!C30 -> 11.5 | C29: =Concentrations!K27 -> 1.1418082 | D29: =Concentrations!L27 -> 0.034211527 | L29: =Masses!E30 -> 0.25316299 | M29: =Masses!H30 -> 0.0049572736
B30: =Masses!B31 -> 12 | E30: =E32+C31 -> 17.101212 | F30: =SQRT(SUMSQ(F32,D31)) -> 0.19942961 | G30: =LN($E$6/E30)/Constants!$B$25 -> 31.931313 | H30: =SQRT((G30*Constants!$B$26)^2+($F$6/$E$6)^2+(1-2*E30/$E$6)*(F30/E30)^2)/Constants!$B$25 -> 0.31708544 | I30: =Constants!$B$15-G30 -> 1989.663 | J30: =Constants!$B$25*CF!E30/Concentrations!I28 -> 0.11884816 | K30: =J30*SQRT((F30/E30)^2+(1-(E30-E32)/(E30))*(Concentrations!J28/Concentrations!I28)^2) -> 0.0023094497 | N30: =AVERAGE(L29,L31) -> 0.26123617 | O30: =SQRT((M29^2+M31^2))/2 -> 0.0035257488 | P30: =J30/N30 -> 0.45494526 | Q30: =P30*SQRT(SUMSQ(K30/J30,O30/N30)) -> 0.010763596 | T30: =J30*10000 -> 1188.4816 | V30: =(T30)*(U30) -> 0 | W30: =P30 -> 0.45494526 | X30: =I30 -> 1989.663
A31: =Masses!C32 -> 12.5 | C31: =Concentrations!K29 -> 1.2019528 | D31: =Concentrations!L29 -> 0.035492974 | L31: =Masses!E32 -> 0.26930936 | M31: =Masses!H32 -> 0.0050148835
B32: =Masses!B33 -> 13 | E32: =E34+C33 -> 15.899259 | F32: =SQRT(SUMSQ(F34,D33)) -> 0.19624581 | G32: =LN($E$6/E32)/Constants!$B$25 -> 34.268554 | H32: =SQRT((G32*Constants!$B$26)^2+($F$6/$E$6)^2+(1-2*E32/$E$6)*(F32/E32)^2)/Constants!$B$25 -> 0.34290216 | I32: =Constants!$B$15-G32 -> 1987.3257 | J32: =Constants!$B$25*CF!E32/Concentrations!I30 -> 0.10299011 | K32: =J32*SQRT((F32/E32)^2+(1-(E32-E34)/(E32))*(Concentrations!J30/Concentrations!I30)^2) -> 0.0019496057 | N32: =AVERAGE(L31,L33) -> 0.26947815 | O32: =SQRT((M31^2+M33^2))/2 -> 0.0034006837 | P32: =J32/N32 -> 0.38218353 | Q32: =P32*SQRT(SUMSQ(K32/J32,O32/N32)) -> 0.0086949744 | T32: =J32*10000 -> 1029.9011 | V32: =(T32)*(U32) -> 0 | W32: =P32 -> 0.38218353 | X32: =I32 -> 1987.3257
A33: =Masses!C34 -> 13.5 | C33: =Concentrations!K31 -> 1.3924698 | D33: =Concentrations!L31 -> 0.036381888 | L33: =Masses!E34 -> 0.26964695 | M33: =Masses!H34 -> 0.004594512
B34: =Masses!B35 -> 14 | E34: =E36+C35 -> 14.506789 | F34: =SQRT(SUMSQ(F36,D35)) -> 0.19284392 | G34: =LN($E$6/E34)/Constants!$B$25 -> 37.208055 | H34: =SQRT((G34*Constants!$B$26)^2+($F$6/$E$6)^2+(1-2*E34/$E$6)*(F34/E34)^2)/Constants!$B$25 -> 0.37746926 | I34: =Constants!$B$15-G34 -> 1984.3862 | J34: =Constants!$B$25*CF!E34/Concentrations!I32 -> 0.085743092 | K34: =J34*SQRT((F34/E34)^2+(1-(E34-E36)/(E34))*(Concentrations!J32/Concentrations!I32)^2) -> 0.0015937967 | N34: =AVERAGE(L33,L35) -> 0.27210446 | O34: =SQRT((M33^2+M35^2))/2 -> 0.0031298635 | P34: =J34/N34 -> 0.31511095 | Q34: =P34*SQRT(SUMSQ(K34/J34,O34/N34)) -> 0.0068880507 | T34: =J34*10000 -> 857.43092 | V34: =(T34)*(U34) -> 0 | W34: =P34 -> 0.31511095 | X34: =I34 -> 1984.3862
A35: =Masses!C36 -> 14.5 | C35: =Concentrations!K33 -> 1.4790156 | D35: =Concentrations!L33 -> 0.036237779 | L35: =Masses!E36 -> 0.27456196 | M35: =Masses!H36 -> 0.0042514282
B36: =Masses!B37 -> 15 | E36: =E38+C37 -> 13.027773 | F36: =SQRT(SUMSQ(F38,D37)) -> 0.18940855 | G36: =LN($E$6/E36)/Constants!$B$25 -> 40.656766 | H36: =SQRT((G36*Constants!$B$26)^2+($F$6/$E$6)^2+(1-2*E36/$E$6)*(F36/E36)^2)/Constants!$B$25 -> 0.42131569 | I36: =Constants!$B$15-G36 -> 1980.9375 | J36: =Constants!$B$25*CF!E36/Concentrations!I34 -> 0.078165185 | K36: =J36*SQRT((F36/E36)^2+(1-(E36-E38)/(E36))*(Concentrations!J34/Concentrations!I34)^2) -> 0.0015340347 | N36: =AVERAGE(L35,L37) -> 0.27098767 | O36: =SQRT((M35^2+M37^2))/2 -> 0.0031914511 | P36: =J36/N36 -> 0.28844554 | Q36: =P36*SQRT(SUMSQ(K36/J36,O36/N36)) -> 0.0066019536 | T36: =J36*10000 -> 781.65185 | V36: =(T36)*(U36) -> 0 | W36: =P36 -> 0.28844554 | X36: =I36 -> 1980.9375
A37: =Masses!C38 -> 15.5 | C37: =Concentrations!K35 -> 1.3389239 | D37: =Concentrations!L35 -> 0.036282236 | L37: =Masses!E38 -> 0.26741339 | M37: =Masses!H38 -> 0.0047609662
B38: =Masses!B39 -> 16 | E38: =E40+C39 -> 11.68885 | F38: =SQRT(SUMSQ(F40,D39)) -> 0.18590105 | G38: =LN($E$6/E38)/Constants!$B$25 -> 44.134818 | H38: =SQRT((G38*Constants!$B$26)^2+($F$6/$E$6)^2+(1-2*E38/$E$6)*(F38/E38)^2)/Constants!$B$25 -> 0.46886782 | I38: =Constants!$B$15-G38 -> 1977.4595 | J38: =Constants!$B$25*CF!E38/Concentrations!I36 -> 0.078305438 | K38: =J38*SQRT((F38/E38)^2+(1-(E38-E40)/(E38))*(Concentrations!J36/Concentrations!I36)^2) -> 0.0016983459 | N38: =AVERAGE(L37,L39) -> 0.26879637 | O38: =SQRT((M37^2+M39^2))/2 -> 0.0034759735 | P38: =J38/N38 -> 0.29131881 | Q38: =P38*SQRT(SUMSQ(K38/J38,O38/N38)) -> 0.0073561785 | T38: =J38*10000 -> 783.05438 | V38: =(T38)*(U38) -> 0 | W38: =P38 -> 0.29131881 | X38: =I38 -> 1977.4595
A39: =Masses!C40 -> 16.5 | C39: =Concentrations!K37 -> 1.162285 | D39: =Concentrations!L37 -> 0.035194273 | L39: =Masses!E40 -> 0.27017935 | M39: =Masses!H40 -> 0.0050658432
B40: =Masses!B41 -> 17 | E40: =E42+C41 -> 10.526565 | F40: =SQRT(SUMSQ(F42,D41)) -> 0.18253921 | G40: =LN($E$6/E40)/Constants!$B$25 -> 47.493733 | H40: =SQRT((G40*Constants!$B$26)^2+($F$6/$E$6)^2+(1-2*E40/$E$6)*(F40/E40)^2)/Constants!$B$25 -> 0.51831663 | I40: =Constants!$B$15-G40 -> 1974.1006 | J40: =Constants!$B$25*CF!E40/Concentrations!I38 -> 0.084789943 | K40: =J40*SQRT((F40/E40)^2+(1-(E40-E42)/(E40))*(Concentrations!J38/Concentrations!I38)^2) -> 0.0021092544 | N40: =AVERAGE(L39,L41) -> 0.27081262 | O40: =SQRT((M39^2+M41^2))/2 -> 0.0035848524 | P40: =J40/N40 -> 0.3130945 | Q40: =P40*SQRT(SUMSQ(K40/J40,O40/N40)) -> 0.008822687 | T40: =J40*10000 -> 847.89943 | V40: =(T40)*(U40) -> 0 | W40: =P40 -> 0.3130945 | X40: =I40 -> 1974.1006
...

Sheet Age vs Depth
E2: CFCS | I2: CF
E3: Age | F3: Depth | G3: mass depth | I3: Age | J3: Depth
E4: =CFCS!E5 -> 0 | F4: {=_xlfn._xlws.FILTER(Masses!C8:'Masses'!C76,(Masses!C8:'Masses'!C76<>""))} -> 0.5 | I4: (yr)
E5: =CFCS!E6 -> 2.299432 | F5: 1.5 | I5: {=_xlfn._xlws.FILTER(CF!G6:'CF'!G74,(CF!G6:'CF'!G74<>""))} -> 0 | J5: {=_xlfn._xlws.FILTER(Masses!B7:'Masses'!B75,(Masses!B7:'Masses'!B75<>""))} -> 0
E6: =CFCS!E7 -> 4.598864 | F6: 2.5 | I6: 1.8030737 | J6: 1
E7: =CFCS!E8 -> 6.898296 | F7: 3.5 | I7: 3.9689391 | J7: 2
E8: =CFCS!E9 -> 9.1977281 | F8: 4.5 | I8: 6.6576703 | J8: 3
E9: =CFCS!E10 -> 11.49716 | F9: 5.5 | I9: 9.5063587 | J9: 4
E10: =CFCS!E11 -> 13.796592 | F10: 6.5 | I10: 12.602628 | J10: 5
E11: =CFCS!E12 -> 16.096024 | F11: 7.5 | I11: 15.720247 | J11: 6
E12: =CFCS!E13 -> 18.395456 | F12: 8.5 | I12: 19.057047 | J12: 7
E13: =CFCS!E14 -> 20.694888 | F13: 9.5 | I13: 22.221721 | J13: 8
